[2022-07-16 19:20:42,520] {taskinstance.py:1179} INFO - Dependencies all met for <TaskInstance: process_files.upload_to_pg manual__2022-07-16T19:20:36.333317+00:00 [queued]>
[2022-07-16 19:20:42,529] {taskinstance.py:1179} INFO - Dependencies all met for <TaskInstance: process_files.upload_to_pg manual__2022-07-16T19:20:36.333317+00:00 [queued]>
[2022-07-16 19:20:42,530] {taskinstance.py:1376} INFO - 
--------------------------------------------------------------------------------
[2022-07-16 19:20:42,530] {taskinstance.py:1377} INFO - Starting attempt 1 of 1
[2022-07-16 19:20:42,530] {taskinstance.py:1378} INFO - 
--------------------------------------------------------------------------------
[2022-07-16 19:20:42,543] {taskinstance.py:1397} INFO - Executing <Task(PostgresOperator): upload_to_pg> on 2022-07-16 19:20:36.333317+00:00
[2022-07-16 19:20:42,549] {standard_task_runner.py:52} INFO - Started process 1884 to run task
[2022-07-16 19:20:42,551] {standard_task_runner.py:79} INFO - Running: ['***', 'tasks', 'run', 'process_files', 'upload_to_pg', 'manual__2022-07-16T19:20:36.333317+00:00', '--job-id', '14', '--raw', '--subdir', 'DAGS_FOLDER/process_files.py', '--cfg-path', '/tmp/tmpo7y5srqu', '--error-file', '/tmp/tmp314_sdpn']
[2022-07-16 19:20:42,551] {standard_task_runner.py:80} INFO - Job 14: Subtask upload_to_pg
[2022-07-16 19:20:42,606] {task_command.py:371} INFO - Running <TaskInstance: process_files.upload_to_pg manual__2022-07-16T19:20:36.333317+00:00 [running]> on host 98d7be6daedb
[2022-07-16 19:20:42,722] {taskinstance.py:1591} INFO - Exporting the following env vars:
AIRFLOW_CTX_DAG_OWNER=***
AIRFLOW_CTX_DAG_ID=process_files
AIRFLOW_CTX_TASK_ID=upload_to_pg
AIRFLOW_CTX_EXECUTION_DATE=2022-07-16T19:20:36.333317+00:00
AIRFLOW_CTX_TRY_NUMBER=1
AIRFLOW_CTX_DAG_RUN_ID=manual__2022-07-16T19:20:36.333317+00:00
[2022-07-16 19:20:42,739] {taskinstance.py:1909} ERROR - Task failed with exception
Traceback (most recent call last):
  File "/home/airflow/.local/lib/python3.7/site-packages/airflow/providers/postgres/operators/postgres.py", line 92, in execute
    self.hook.run(self.sql, self.autocommit, parameters=self.parameters)
  File "/home/airflow/.local/lib/python3.7/site-packages/airflow/hooks/dbapi.py", line 204, in run
    with closing(self.get_conn()) as conn:
  File "/home/airflow/.local/lib/python3.7/site-packages/airflow/providers/postgres/hooks/postgres.py", line 86, in get_conn
    conn = deepcopy(self.connection or self.get_connection(conn_id))
  File "/home/airflow/.local/lib/python3.7/site-packages/airflow/hooks/base.py", line 67, in get_connection
    conn = Connection.get_connection_from_secrets(conn_id)
  File "/home/airflow/.local/lib/python3.7/site-packages/airflow/models/connection.py", line 430, in get_connection_from_secrets
    raise AirflowNotFoundException(f"The conn_id `{conn_id}` isn't defined")
airflow.exceptions.AirflowNotFoundException: The conn_id `pg_conn` isn't defined
[2022-07-16 19:20:42,742] {taskinstance.py:1420} INFO - Marking task as FAILED. dag_id=process_files, task_id=upload_to_pg, execution_date=20220716T192036, start_date=20220716T192042, end_date=20220716T192042
[2022-07-16 19:20:42,750] {standard_task_runner.py:97} ERROR - Failed to execute job 14 for task upload_to_pg (The conn_id `pg_conn` isn't defined; 1884)
[2022-07-16 19:20:42,763] {local_task_job.py:156} INFO - Task exited with return code 1
[2022-07-16 19:20:42,797] {local_task_job.py:273} INFO - 0 downstream tasks scheduled from follow-on schedule check
