[2022-07-16 19:26:37,806] {taskinstance.py:1179} INFO - Dependencies all met for <TaskInstance: process_files.upload_to_pg manual__2022-07-16T19:20:36.333317+00:00 [queued]>
[2022-07-16 19:26:37,818] {taskinstance.py:1179} INFO - Dependencies all met for <TaskInstance: process_files.upload_to_pg manual__2022-07-16T19:20:36.333317+00:00 [queued]>
[2022-07-16 19:26:37,818] {taskinstance.py:1376} INFO - 
--------------------------------------------------------------------------------
[2022-07-16 19:26:37,818] {taskinstance.py:1377} INFO - Starting attempt 2 of 2
[2022-07-16 19:26:37,818] {taskinstance.py:1378} INFO - 
--------------------------------------------------------------------------------
[2022-07-16 19:26:37,835] {taskinstance.py:1397} INFO - Executing <Task(PostgresOperator): upload_to_pg> on 2022-07-16 19:20:36.333317+00:00
[2022-07-16 19:26:37,842] {standard_task_runner.py:52} INFO - Started process 2169 to run task
[2022-07-16 19:26:37,844] {standard_task_runner.py:79} INFO - Running: ['***', 'tasks', 'run', 'process_files', 'upload_to_pg', 'manual__2022-07-16T19:20:36.333317+00:00', '--job-id', '15', '--raw', '--subdir', 'DAGS_FOLDER/process_files.py', '--cfg-path', '/tmp/tmp87oni4ya', '--error-file', '/tmp/tmpdfwblm1z']
[2022-07-16 19:26:37,845] {standard_task_runner.py:80} INFO - Job 15: Subtask upload_to_pg
[2022-07-16 19:26:37,897] {task_command.py:371} INFO - Running <TaskInstance: process_files.upload_to_pg manual__2022-07-16T19:20:36.333317+00:00 [running]> on host 98d7be6daedb
[2022-07-16 19:26:38,008] {taskinstance.py:1591} INFO - Exporting the following env vars:
AIRFLOW_CTX_DAG_OWNER=***
AIRFLOW_CTX_DAG_ID=process_files
AIRFLOW_CTX_TASK_ID=upload_to_pg
AIRFLOW_CTX_EXECUTION_DATE=2022-07-16T19:20:36.333317+00:00
AIRFLOW_CTX_TRY_NUMBER=2
AIRFLOW_CTX_DAG_RUN_ID=manual__2022-07-16T19:20:36.333317+00:00
[2022-07-16 19:26:38,017] {base.py:68} INFO - Using connection ID 'pg_conn' for task execution.
[2022-07-16 19:26:38,019] {taskinstance.py:1909} ERROR - Task failed with exception
Traceback (most recent call last):
  File "/home/airflow/.local/lib/python3.7/site-packages/airflow/providers/postgres/operators/postgres.py", line 92, in execute
    self.hook.run(self.sql, self.autocommit, parameters=self.parameters)
  File "/home/airflow/.local/lib/python3.7/site-packages/airflow/hooks/dbapi.py", line 204, in run
    with closing(self.get_conn()) as conn:
  File "/home/airflow/.local/lib/python3.7/site-packages/airflow/providers/postgres/hooks/postgres.py", line 113, in get_conn
    self.conn = psycopg2.connect(**conn_args)
  File "/home/airflow/.local/lib/python3.7/site-packages/psycopg2/__init__.py", line 122, in connect
    conn = _connect(dsn, connection_factory=connection_factory, **kwasync)
psycopg2.OperationalError: connection to server at "ekg-foundations-postgres-1" (172.18.0.3), port 5432 failed: fe_sendauth: no password supplied

[2022-07-16 19:26:38,026] {taskinstance.py:1420} INFO - Marking task as FAILED. dag_id=process_files, task_id=upload_to_pg, execution_date=20220716T192036, start_date=20220716T192637, end_date=20220716T192638
[2022-07-16 19:26:38,036] {standard_task_runner.py:97} ERROR - Failed to execute job 15 for task upload_to_pg (connection to server at "ekg-foundations-postgres-1" (172.18.0.3), port 5432 failed: fe_sendauth: no password supplied
; 2169)
[2022-07-16 19:26:38,096] {local_task_job.py:156} INFO - Task exited with return code 1
[2022-07-16 19:26:38,132] {local_task_job.py:273} INFO - 0 downstream tasks scheduled from follow-on schedule check
