[2022-07-14 22:47:49,743] {taskinstance.py:1179} INFO - Dependencies all met for <TaskInstance: process_files.download manual__2022-07-14T22:47:46.166450+00:00 [queued]>
[2022-07-14 22:47:49,755] {taskinstance.py:1179} INFO - Dependencies all met for <TaskInstance: process_files.download manual__2022-07-14T22:47:46.166450+00:00 [queued]>
[2022-07-14 22:47:49,756] {taskinstance.py:1376} INFO - 
--------------------------------------------------------------------------------
[2022-07-14 22:47:49,756] {taskinstance.py:1377} INFO - Starting attempt 1 of 1
[2022-07-14 22:47:49,756] {taskinstance.py:1378} INFO - 
--------------------------------------------------------------------------------
[2022-07-14 22:47:49,773] {taskinstance.py:1397} INFO - Executing <Task(PythonOperator): download> on 2022-07-14 22:47:46.166450+00:00
[2022-07-14 22:47:49,781] {standard_task_runner.py:52} INFO - Started process 1529 to run task
[2022-07-14 22:47:49,784] {standard_task_runner.py:79} INFO - Running: ['***', 'tasks', 'run', 'process_files', 'download', 'manual__2022-07-14T22:47:46.166450+00:00', '--job-id', '12', '--raw', '--subdir', 'DAGS_FOLDER/process_files.py', '--cfg-path', '/tmp/tmpf80e61a2', '--error-file', '/tmp/tmp82iowq2n']
[2022-07-14 22:47:49,784] {standard_task_runner.py:80} INFO - Job 12: Subtask download
[2022-07-14 22:47:49,855] {task_command.py:371} INFO - Running <TaskInstance: process_files.download manual__2022-07-14T22:47:46.166450+00:00 [running]> on host 4bf3acff5795
[2022-07-14 22:47:49,930] {taskinstance.py:1591} INFO - Exporting the following env vars:
AIRFLOW_CTX_DAG_OWNER=***
AIRFLOW_CTX_DAG_ID=process_files
AIRFLOW_CTX_TASK_ID=download
AIRFLOW_CTX_EXECUTION_DATE=2022-07-14T22:47:46.166450+00:00
AIRFLOW_CTX_TRY_NUMBER=1
AIRFLOW_CTX_DAG_RUN_ID=manual__2022-07-14T22:47:46.166450+00:00
[2022-07-14 22:47:50,134] {taskinstance.py:1909} ERROR - Task failed with exception
Traceback (most recent call last):
  File "/home/airflow/.local/lib/python3.7/site-packages/airflow/operators/python.py", line 171, in execute
    return_value = self.execute_callable()
  File "/home/airflow/.local/lib/python3.7/site-packages/airflow/operators/python.py", line 189, in execute_callable
    return self.python_callable(*self.op_args, **self.op_kwargs)
  File "/opt/airflow/dags/process_files.py", line 13, in download_file
    with open('/usr/local/airflow/dags/files/world.sql', 'w') as outfile:
FileNotFoundError: [Errno 2] No such file or directory: '/usr/local/airflow/dags/files/world.sql'
[2022-07-14 22:47:50,148] {taskinstance.py:1420} INFO - Marking task as FAILED. dag_id=process_files, task_id=download, execution_date=20220714T224746, start_date=20220714T224749, end_date=20220714T224750
[2022-07-14 22:47:50,163] {standard_task_runner.py:97} ERROR - Failed to execute job 12 for task download ([Errno 2] No such file or directory: '/usr/local/airflow/dags/files/world.sql'; 1529)
[2022-07-14 22:47:50,196] {local_task_job.py:156} INFO - Task exited with return code 1
[2022-07-14 22:47:50,255] {local_task_job.py:273} INFO - 0 downstream tasks scheduled from follow-on schedule check
