[2022-07-14 22:42:08,197] {taskinstance.py:1179} INFO - Dependencies all met for <TaskInstance: process_files.download manual__2022-07-14T22:42:05.826259+00:00 [queued]>
[2022-07-14 22:42:08,208] {taskinstance.py:1179} INFO - Dependencies all met for <TaskInstance: process_files.download manual__2022-07-14T22:42:05.826259+00:00 [queued]>
[2022-07-14 22:42:08,208] {taskinstance.py:1376} INFO - 
--------------------------------------------------------------------------------
[2022-07-14 22:42:08,208] {taskinstance.py:1377} INFO - Starting attempt 1 of 1
[2022-07-14 22:42:08,209] {taskinstance.py:1378} INFO - 
--------------------------------------------------------------------------------
[2022-07-14 22:42:08,221] {taskinstance.py:1397} INFO - Executing <Task(PythonOperator): download> on 2022-07-14 22:42:05.826259+00:00
[2022-07-14 22:42:08,229] {standard_task_runner.py:52} INFO - Started process 1260 to run task
[2022-07-14 22:42:08,233] {standard_task_runner.py:79} INFO - Running: ['***', 'tasks', 'run', 'process_files', 'download', 'manual__2022-07-14T22:42:05.826259+00:00', '--job-id', '8', '--raw', '--subdir', 'DAGS_FOLDER/process_files.py', '--cfg-path', '/tmp/tmp23w9snk3', '--error-file', '/tmp/tmpsrnmsju_']
[2022-07-14 22:42:08,233] {standard_task_runner.py:80} INFO - Job 8: Subtask download
[2022-07-14 22:42:08,308] {task_command.py:371} INFO - Running <TaskInstance: process_files.download manual__2022-07-14T22:42:05.826259+00:00 [running]> on host 4bf3acff5795
[2022-07-14 22:42:08,385] {taskinstance.py:1591} INFO - Exporting the following env vars:
AIRFLOW_CTX_DAG_OWNER=***
AIRFLOW_CTX_DAG_ID=process_files
AIRFLOW_CTX_TASK_ID=download
AIRFLOW_CTX_EXECUTION_DATE=2022-07-14T22:42:05.826259+00:00
AIRFLOW_CTX_TRY_NUMBER=1
AIRFLOW_CTX_DAG_RUN_ID=manual__2022-07-14T22:42:05.826259+00:00
[2022-07-14 22:42:08,556] {taskinstance.py:1909} ERROR - Task failed with exception
Traceback (most recent call last):
  File "/home/airflow/.local/lib/python3.7/site-packages/airflow/operators/python.py", line 171, in execute
    return_value = self.execute_callable()
  File "/home/airflow/.local/lib/python3.7/site-packages/airflow/operators/python.py", line 189, in execute_callable
    return self.python_callable(*self.op_args, **self.op_kwargs)
  File "/opt/airflow/dags/process_files.py", line 13, in download_file
    with open('/usr/local/airflow/dags/files/forex_rates.json', 'a') as outfile:
FileNotFoundError: [Errno 2] No such file or directory: '/usr/local/airflow/dags/files/forex_rates.json'
[2022-07-14 22:42:08,566] {taskinstance.py:1420} INFO - Marking task as FAILED. dag_id=process_files, task_id=download, execution_date=20220714T224205, start_date=20220714T224208, end_date=20220714T224208
[2022-07-14 22:42:08,579] {standard_task_runner.py:97} ERROR - Failed to execute job 8 for task download ([Errno 2] No such file or directory: '/usr/local/airflow/dags/files/forex_rates.json'; 1260)
[2022-07-14 22:42:08,604] {local_task_job.py:156} INFO - Task exited with return code 1
[2022-07-14 22:42:08,650] {local_task_job.py:273} INFO - 0 downstream tasks scheduled from follow-on schedule check
