[2022-07-16 19:36:43,525] {taskinstance.py:1179} INFO - Dependencies all met for <TaskInstance: process_files.upload_to_pg manual__2022-07-16T19:36:23.841544+00:00 [queued]>
[2022-07-16 19:36:43,534] {taskinstance.py:1179} INFO - Dependencies all met for <TaskInstance: process_files.upload_to_pg manual__2022-07-16T19:36:23.841544+00:00 [queued]>
[2022-07-16 19:36:43,534] {taskinstance.py:1376} INFO - 
--------------------------------------------------------------------------------
[2022-07-16 19:36:43,534] {taskinstance.py:1377} INFO - Starting attempt 1 of 1
[2022-07-16 19:36:43,534] {taskinstance.py:1378} INFO - 
--------------------------------------------------------------------------------
[2022-07-16 19:36:43,546] {taskinstance.py:1397} INFO - Executing <Task(PostgresOperator): upload_to_pg> on 2022-07-16 19:36:23.841544+00:00
[2022-07-16 19:36:43,552] {standard_task_runner.py:52} INFO - Started process 2966 to run task
[2022-07-16 19:36:43,554] {standard_task_runner.py:79} INFO - Running: ['***', 'tasks', 'run', 'process_files', 'upload_to_pg', 'manual__2022-07-16T19:36:23.841544+00:00', '--job-id', '20', '--raw', '--subdir', 'DAGS_FOLDER/process_files.py', '--cfg-path', '/tmp/tmp9rmfucvs', '--error-file', '/tmp/tmpymogg2b_']
[2022-07-16 19:36:43,554] {standard_task_runner.py:80} INFO - Job 20: Subtask upload_to_pg
[2022-07-16 19:36:43,612] {task_command.py:371} INFO - Running <TaskInstance: process_files.upload_to_pg manual__2022-07-16T19:36:23.841544+00:00 [running]> on host 98d7be6daedb
[2022-07-16 19:36:43,731] {taskinstance.py:1591} INFO - Exporting the following env vars:
AIRFLOW_CTX_DAG_OWNER=***
AIRFLOW_CTX_DAG_ID=process_files
AIRFLOW_CTX_TASK_ID=upload_to_pg
AIRFLOW_CTX_EXECUTION_DATE=2022-07-16T19:36:23.841544+00:00
AIRFLOW_CTX_TRY_NUMBER=1
AIRFLOW_CTX_DAG_RUN_ID=manual__2022-07-16T19:36:23.841544+00:00
[2022-07-16 19:36:43,738] {base.py:68} INFO - Using connection ID 'pg_conn' for task execution.
[2022-07-16 19:36:43,747] {taskinstance.py:1909} ERROR - Task failed with exception
Traceback (most recent call last):
  File "/home/airflow/.local/lib/python3.7/site-packages/airflow/providers/postgres/operators/postgres.py", line 92, in execute
    self.hook.run(self.sql, self.autocommit, parameters=self.parameters)
  File "/home/airflow/.local/lib/python3.7/site-packages/airflow/hooks/dbapi.py", line 204, in run
    with closing(self.get_conn()) as conn:
  File "/home/airflow/.local/lib/python3.7/site-packages/airflow/providers/postgres/hooks/postgres.py", line 113, in get_conn
    self.conn = psycopg2.connect(**conn_args)
  File "/home/airflow/.local/lib/python3.7/site-packages/psycopg2/__init__.py", line 122, in connect
    conn = _connect(dsn, connection_factory=connection_factory, **kwasync)
psycopg2.OperationalError: could not translate host name "***" to address: Name or service not known

[2022-07-16 19:36:43,754] {taskinstance.py:1420} INFO - Marking task as FAILED. dag_id=process_files, task_id=upload_to_pg, execution_date=20220716T193623, start_date=20220716T193643, end_date=20220716T193643
[2022-07-16 19:36:43,762] {standard_task_runner.py:97} ERROR - Failed to execute job 20 for task upload_to_pg (could not translate host name "***" to address: Name or service not known
; 2966)
[2022-07-16 19:36:43,806] {local_task_job.py:156} INFO - Task exited with return code 1
[2022-07-16 19:36:43,841] {local_task_job.py:273} INFO - 0 downstream tasks scheduled from follow-on schedule check
